Traceback (most recent call last):
  File "/opt/homebrew/lib/python3.11/site-packages/jupyter_cache/executors/utils.py", line 58, in single_nb_execution
    executenb(
  File "/opt/homebrew/lib/python3.11/site-packages/nbclient/client.py", line 1314, in execute
    return NotebookClient(nb=nb, resources=resources, km=km, **kwargs).execute()
           ^^^^^^^^^^^^^^^^^^^^^^^^^^^^^^^^^^^^^^^^^^^^^^^^^^^^^^^^^^^^^^^^^^^^^
  File "/opt/homebrew/lib/python3.11/site-packages/jupyter_core/utils/__init__.py", line 165, in wrapped
    return loop.run_until_complete(inner)
           ^^^^^^^^^^^^^^^^^^^^^^^^^^^^^^
  File "/opt/homebrew/Cellar/python@3.11/3.11.5/Frameworks/Python.framework/Versions/3.11/lib/python3.11/asyncio/base_events.py", line 653, in run_until_complete
    return future.result()
           ^^^^^^^^^^^^^^^
  File "/opt/homebrew/lib/python3.11/site-packages/nbclient/client.py", line 709, in async_execute
    await self.async_execute_cell(
  File "/opt/homebrew/lib/python3.11/site-packages/nbclient/client.py", line 1062, in async_execute_cell
    await self._check_raise_for_error(cell, cell_index, exec_reply)
  File "/opt/homebrew/lib/python3.11/site-packages/nbclient/client.py", line 918, in _check_raise_for_error
    raise CellExecutionError.from_cell_and_msg(cell, exec_reply_content)
nbclient.exceptions.CellExecutionError: An error occurred while executing the following cell:
------------------
%run woontevredenheid.ipynb
------------------


[0;31m---------------------------------------------------------------------------[0m
[0;31mNameError[0m                                 Traceback (most recent call last)
Cell [0;32mIn[8], line 1[0m
[0;32m----> 1[0m [43mget_ipython[49m[43m([49m[43m)[49m[38;5;241;43m.[39;49m[43mrun_line_magic[49m[43m([49m[38;5;124;43m'[39;49m[38;5;124;43mrun[39;49m[38;5;124;43m'[39;49m[43m,[49m[43m [49m[38;5;124;43m'[39;49m[38;5;124;43mwoontevredenheid.ipynb[39;49m[38;5;124;43m'[39;49m[43m)[49m

File [0;32m/opt/homebrew/lib/python3.11/site-packages/IPython/core/interactiveshell.py:2480[0m, in [0;36mInteractiveShell.run_line_magic[0;34m(self, magic_name, line, _stack_depth)[0m
[1;32m   2478[0m     kwargs[[38;5;124m'[39m[38;5;124mlocal_ns[39m[38;5;124m'[39m] [38;5;241m=[39m [38;5;28mself[39m[38;5;241m.[39mget_local_scope(stack_depth)
[1;32m   2479[0m [38;5;28;01mwith[39;00m [38;5;28mself[39m[38;5;241m.[39mbuiltin_trap:
[0;32m-> 2480[0m     result [38;5;241m=[39m [43mfn[49m[43m([49m[38;5;241;43m*[39;49m[43margs[49m[43m,[49m[43m [49m[38;5;241;43m*[39;49m[38;5;241;43m*[39;49m[43mkwargs[49m[43m)[49m
[1;32m   2482[0m [38;5;66;03m# The code below prevents the output from being displayed[39;00m
[1;32m   2483[0m [38;5;66;03m# when using magics with decorator @output_can_be_silenced[39;00m
[1;32m   2484[0m [38;5;66;03m# when the last Python token in the expression is a ';'.[39;00m
[1;32m   2485[0m [38;5;28;01mif[39;00m [38;5;28mgetattr[39m(fn, magic[38;5;241m.[39mMAGIC_OUTPUT_CAN_BE_SILENCED, [38;5;28;01mFalse[39;00m):

File [0;32m/opt/homebrew/lib/python3.11/site-packages/IPython/core/magics/execution.py:737[0m, in [0;36mExecutionMagics.run[0;34m(self, parameter_s, runner, file_finder)[0m
[1;32m    735[0m     [38;5;28;01mwith[39;00m preserve_keys([38;5;28mself[39m[38;5;241m.[39mshell[38;5;241m.[39muser_ns, [38;5;124m'[39m[38;5;124m__file__[39m[38;5;124m'[39m):
[1;32m    736[0m         [38;5;28mself[39m[38;5;241m.[39mshell[38;5;241m.[39muser_ns[[38;5;124m'[39m[38;5;124m__file__[39m[38;5;124m'[39m] [38;5;241m=[39m filename
[0;32m--> 737[0m         [38;5;28;43mself[39;49m[38;5;241;43m.[39;49m[43mshell[49m[38;5;241;43m.[39;49m[43msafe_execfile_ipy[49m[43m([49m[43mfilename[49m[43m,[49m[43m [49m[43mraise_exceptions[49m[38;5;241;43m=[39;49m[38;5;28;43;01mTrue[39;49;00m[43m)[49m
[1;32m    738[0m     [38;5;28;01mreturn[39;00m
[1;32m    740[0m [38;5;66;03m# Control the response to exit() calls made by the script being run[39;00m

File [0;32m/opt/homebrew/lib/python3.11/site-packages/IPython/core/interactiveshell.py:3005[0m, in [0;36mInteractiveShell.safe_execfile_ipy[0;34m(self, fname, shell_futures, raise_exceptions)[0m
[1;32m   3003[0m result [38;5;241m=[39m [38;5;28mself[39m[38;5;241m.[39mrun_cell(cell, silent[38;5;241m=[39m[38;5;28;01mTrue[39;00m, shell_futures[38;5;241m=[39mshell_futures)
[1;32m   3004[0m [38;5;28;01mif[39;00m raise_exceptions:
[0;32m-> 3005[0m     [43mresult[49m[38;5;241;43m.[39;49m[43mraise_error[49m[43m([49m[43m)[49m
[1;32m   3006[0m [38;5;28;01melif[39;00m [38;5;129;01mnot[39;00m result[38;5;241m.[39msuccess:
[1;32m   3007[0m     [38;5;28;01mbreak[39;00m

File [0;32m/opt/homebrew/lib/python3.11/site-packages/IPython/core/interactiveshell.py:308[0m, in [0;36mExecutionResult.raise_error[0;34m(self)[0m
[1;32m    306[0m     [38;5;28;01mraise[39;00m [38;5;28mself[39m[38;5;241m.[39merror_before_exec
[1;32m    307[0m [38;5;28;01mif[39;00m [38;5;28mself[39m[38;5;241m.[39merror_in_exec [38;5;129;01mis[39;00m [38;5;129;01mnot[39;00m [38;5;28;01mNone[39;00m:
[0;32m--> 308[0m     [38;5;28;01mraise[39;00m [38;5;28mself[39m[38;5;241m.[39merror_in_exec

    [0;31m[... skipping hidden 1 frame][0m

File [0;32m/var/folders/ml/tgl_vvsx7ln3q81h8trtk4j00000gn/T/ipykernel_93480/2537820901.py:22[0m
[1;32m     19[0m group2_data [38;5;241m=[39m data[data[[38;5;124m'[39m[38;5;124mProvince[39m[38;5;124m'[39m][38;5;241m.[39misin(group2_provinces)]
[1;32m     21[0m [38;5;66;03m# Calculate the mean happiness for each group[39;00m
[0;32m---> 22[0m group1_mean [38;5;241m=[39m group1_data[[43myears[49m][38;5;241m.[39mmean()
[1;32m     23[0m group2_mean [38;5;241m=[39m group2_data[years][38;5;241m.[39mmean()
[1;32m     25[0m [38;5;66;03m# Prepare the data for plotting[39;00m

[0;31mNameError[0m: name 'years' is not defined

